Workbook

Sheet GRE-Remitente
B1: GUIA REMISION ELECTRÓNICA REMITENTE
B2: N° | C2: DATO | D2: NIVEL | E2: CONDICIÓN INFORMÁTICA | F2: TIPO Y LONGITUD | G2: FORMATO | H2: TAG UBL | I2: VALIDACIÓN / CONDICIÓN | J2: TIPO DE RETORNO | K2: CODIGO RETORNO | L2: MENSAJE DE RETORNO | M2: REST o XSL | N2: LISTADOS
B3: - | C3: -
B4: Datos de guía de remisión
B5: 1 | C5: Versión del UBL | D5: Global | E5: M | F5: an..3 | G5: 2.1 | H5: /DespatchAdvice/cbc:UBLVersionID | I5: No existe el Tag UBL o es vacío | J5: ERROR | K5: 2111 | L5: =VLOOKUP(K5,[1]CódigosRetorno!$A$2:$B$1996,2,FALSE) -> El XML no contiene el tag o no existe informacion de UBLVersionID | M5: XSL
I6: El valor del Tag UBL es diferente a '2.1' | J6: ERROR | K6: 2110 | L6: =VLOOKUP(K6,[1]CódigosRetorno!$A$2:$B$1996,2,FALSE) -> UBLVersionID - La versión del UBL no es correcta | M6: XSL
B7: =+B5+1 -> 2 | C7: Versión de la estructura del documento | D7: Global | E7: M | F7: an..3 | G7: 2.0 | H7: /DespatchAdvice/cbc:CustomizationID | I7: No existe el Tag UBL o es vacío | J7: ERROR | K7: 2113 | L7: =VLOOKUP(K7,[1]CódigosRetorno!$A$2:$B$1996,2,FALSE) -> El XML no contiene el tag o no existe informacion de CustomizationID | M7: XSL
I8: El valor del Tag UBL es diferente a '2.0' | J8: ERROR | K8: 2112 | L8: =VLOOKUP(K8,[1]CódigosRetorno!$A$2:$B$1996,2,FALSE) -> CustomizationID - La version del documento no es correcta | M8: XSL
B9: =+B7+1 -> 3 | C9: Numeracion, conformada por serie y Número correlativo | D9: Global | E9: M | F9: an..13 | G9: T###-NNNNNNNN | H9: /DespatchAdvice/cbc:ID | I9: El formato del Tag UBL es diferente a: [T][A-Z0-9]{3}-[0-9]{1,8} | J9: ERROR | K9: 1001 | L9: =VLOOKUP(K9,[1]CódigosRetorno!$A$2:$B$1996,2,FALSE) -> ID - El dato SERIE-CORRELATIVO no cumple con el formato de acuerdo al tipo de comprobante | M9: XSL
I10: El número de serie del Tag UBL es diferente al número de serie del archivo | J10: ERROR | K10: 1035 | L10: =VLOOKUP(K10,[1]CódigosRetorno!$A$2:$B$1996,2,FALSE) -> Numero de Serie del nombre del archivo no coincide con el consignado en el contenido del archivo XML | M10: XSL
I11: El número de documento del Tag UBL es diferente al número de documento del archivo | J11: ERROR | K11: 1036 | L11: =VLOOKUP(K11,[1]CódigosRetorno!$A$2:$B$1996,2,FALSE) -> Número de documento en el nombre del archivo no coincide con el consignado en el contenido del XML | M11: XSL
I12: El valor del Tag UBL se encuentra en el listado con indicador de estado igual a 1 | J12: ERROR | K12: 1033 | L12: =VLOOKUP(K12,[1]CódigosRetorno!$A$2:$B$1996,2,FALSE) -> El comprobante fue registrado previamente con otros datos | M12: REST | N12: Comprobantes de pago electrónico
I13: El valor del Tag UBL se encuentra en el listado con indicador de estado igual a 2 | J13: ERROR | K13: 1032 | L13: =VLOOKUP(K13,[1]CódigosRetorno!$A$2:$B$1996,2,FALSE) -> El comprobante ya esta informado y se encuentra con estado anulado o rechazado | M13: REST | N13: Comprobantes de pago electrónico
B14: =+B9+1 -> 4 | C14: Fecha de emisión | D14: Global | E14: M | F14: an10 | G14: YYYY-MM-DD | H14: /DespatchAdvice/cbc:IssueDate | I14: El valor del Tag UBL no cumple con el formato establecido | J14: ERROR | K14: 3436 | L14: =VLOOKUP(K14,[1]CódigosRetorno!$A$2:$B$1996,2,FALSE) -> El campo de fecha de emision no cumple con el formato establecido | M14: XSL
I15: La diferencia entre la fecha de recepción del XML y el valor del Tag UBL es mayor al límite del listado (1 día) | J15: ERROR | K15: 2108 | L15: =VLOOKUP(K15,[1]CódigosRetorno!$A$2:$B$1996,2,FALSE) -> Presentacion fuera de fecha | M15: REST | N15: Parámetros (004)
I16: El valor del Tag UBL es mayor a la fecha de recepción (TODAY) o es 12/07/2022 | J16: ERROR | K16: 2329 | L16: =VLOOKUP(K16,[1]CódigosRetorno!$A$2:$B$1996,2,FALSE) -> La fecha de emision se encuentra fuera del limite permitido | M16: XSL
B17: =+B14+1 -> 5 | C17: Hora de emisión | D17: Global | E17: M | F17: an8 | G17: hh:mm:ss | H17: /DespatchAdvice/cbc:IssueTime | I17: No existe el Tag UBL | J17: ERROR | K17: 3437 | L17: =VLOOKUP(K17,[1]CódigosRetorno!$A$2:$B$1996,2,FALSE) -> No existe informacion en el campo de hora de emision | M17: XSL
I18: El valor del Tag UBL no cumple con el formato establecido | J18: ERROR | K18: 3438 | L18: =VLOOKUP(K18,[1]CódigosRetorno!$A$2:$B$1996,2,FALSE) -> El campo de hora de emision no cumple con el formato establecido | M18: XSL
B19: =+B17+1 -> 6 | C19: Tipo de documento (Guia) | D19: Global | E19: M | F19: an2 | G19: "09" | H19: /DespatchAdvice/cbc:DespatchAdviceTypeCode | I19: No existe el Tag UBL o es vacío | J19: ERROR | K19: 1050 | L19: =VLOOKUP(K19,[1]CódigosRetorno!$A$2:$B$1996,2,FALSE) -> El XML no contiene informacion en el tag DespatchAdviceTypeCode. | M19: XSL
I20: El valor del Tag UBL es diferente a '09' | J20: ERROR | K20: 1051 | L20: =VLOOKUP(K20,[1]CódigosRetorno!$A$2:$B$1996,2,FALSE) -> DespatchAdviceTypeCode - El valor del tipo de guía es inválido. | M20: XSL
G21: "PE:SUNAT" | H21: @listAgencyName | I21: Si existe el atributo, el valor ingresado es diferente a 'PE:SUNAT' | J21: OBSERV | K21: 4251 | L21: =VLOOKUP(K21,[1]CódigosRetorno!$A$2:$B$1996,2,FALSE) -> El dato ingresado como atributo @listAgencyName es incorrecto. | M21: XSL
G22: "Tipo de Documento" | H22: @listName | I22: Si existe el atributo, el valor ingresado es diferente a 'Tipo de Documento' | J22: OBSERV | K22: 4252 | L22: =VLOOKUP(K22,[1]CódigosRetorno!$A$2:$B$1996,2,FALSE) -> El dato ingresado como atributo @listName es incorrecto. | M22: XSL
G23: "urn:pe:gob:sunat:cpe:see:gem:catalogos:catalogo01" | H23: @listURI | I23: Si existe el atributo, el valor ingresado es diferente a 'urn:pe:gob:sunat:cpe:see:gem:catalogos:catalogo01' | J23: OBSERV | K23: 4253 | L23: =VLOOKUP(K23,[1]CódigosRetorno!$A$2:$B$1996,2,FALSE) -> El dato ingresado como atributo @listURI es incorrecto. | M23: XSL
B24: =+B19+1 -> 7 | C24: Observaciones (Texto) | D24: Global | E24: C | F24: an..250 | H24: /DespatchAdvice/cbc:Note | I24: Si el Tag UBL existe, el formato del Tag UBL es diferente a alfanumérico de hasta 250 caracteres o es vacío (se considera cualquier carácter incluido espacio, no se permite ningún otro 'whitespace character': salto de línea, tab, fin de línea, etc. Tampoco se permite solo espacios en blanco) | J24: OBSERV | K24: 4186 | L24: =VLOOKUP(K24,[1]CódigosRetorno!$A$2:$B$1996,2,FALSE) -> cbc:Note - El campo observaciones supera la cantidad maxima especificada (250 carácteres). | M24: XSL
B25: Datos del Remitente
B26: =B24+1 -> 8 | C26: Tipo y número de documento de identidad del remitente | D26: Global | E26: M | F26: an1 | G26: "6" | H26: /DespatchAdvice/cac:DespatchSupplierParty/cac:Party/cac:PartyIdentification/cbc:ID@schemeID (Tipo de documento de identidad del remitente) | I26: No existe el atributo o es vacío | J26: ERROR | K26: 2678 | L26: =VLOOKUP(K26,[1]CódigosRetorno!$A$2:$B$1996,2,FALSE) -> El XML no contiene el atributo o no existe información del tipo de documento del emisor | M26: XSL
I27: El valor del atributo es diferente a '6' | J27: ERROR | K27: 2511 | L27: =VLOOKUP(K27,[1]CódigosRetorno!$A$2:$B$1996,2,FALSE) -> El tipo de documento no es aceptado. | M27: XSL
G28: "Documento de Identidad" | H28: @schemeName | I28: Si existe el atributo, el valor ingresado es diferente a 'Documento de Identidad' | J28: OBSERV | K28: 4255 | L28: =VLOOKUP(K28,[1]CódigosRetorno!$A$2:$B$1996,2,FALSE) -> El dato ingresado como atributo @schemeName es incorrecto. | M28: XSL
G29: "PE:SUNAT" | H29: @schemeAgencyName | I29: Si existe el atributo, el valor ingresado es diferente a 'PE:SUNAT' | J29: OBSERV | K29: 4256 | L29: =VLOOKUP(K29,[1]CódigosRetorno!$A$2:$B$1996,2,FALSE) -> El dato ingresado como atributo @schemeAgencyName es incorrecto. | M29: XSL
G30: "urn:pe:gob:sunat:cpe:see:gem:catalogos:catalogo06" | H30: @schemeURI | I30: Si existe el atributo, el valor ingresado es diferente a 'urn:pe:gob:sunat:cpe:see:gem:catalogos:catalogo06' | J30: OBSERV | K30: 4257 | L30: =VLOOKUP(K30,[1]CódigosRetorno!$A$2:$B$1996,2,FALSE) -> El dato ingresado como atributo @schemeURI es incorrecto. | M30: XSL
F31: an11 | G31: n11 | H31: /DespatchAdvice/cac:DespatchSupplierParty/cac:Party/cac:PartyIdentification/cbc:ID (Número de documento de identidad del remitente) | I31: El Tag UBL es diferente al RUC del nombre del XML | J31: ERROR | K31: 1034 | L31: =VLOOKUP(K31,[1]CódigosRetorno!$A$2:$B$1996,2,FALSE) -> Número de RUC del nombre del archivo no coincide con el consignado en el contenido del archivo XML | M31: XSL
I32: El valor del Tag UBL tiene un ind_estado diferente '00' en el listado | J32: ERROR | K32: 2010 | L32: =VLOOKUP(K32,[1]CódigosRetorno!$A$2:$B$1996,2,FALSE) -> El contribuyente no esta activo | M32: REST | N32: Contribuyentes
I33: El valor del Tag UBL tiene un ind_condicion diferente a '00' en el listado | J33: ERROR | K33: 2011 | L33: =VLOOKUP(K33,[1]CódigosRetorno!$A$2:$B$1996,2,FALSE) -> El contribuyente no esta habido | M33: REST | N33: Contribuyentes
I34: Se encuentra afecto exclusivamente solo a los tributos Renta de primera categoría, Renta de segunda categoría o Renta de cuarta categoría (no está afecto a ningún otro tributo distinto de los indicados) | J34: ERROR | K34: 3439 | L34: =VLOOKUP(K34,[1]CódigosRetorno!$A$2:$B$1996,2,FALSE) -> El RUC no esta afecto a los tributos autorizados | M34: REST | N34: Afectación
B35: =+B26+1 -> 9 | C35: Apellidos y nombres, denominación o razón social del remitente | D35: Global | E35: M | F35: an..250 | H35: /DespatchAdvice/cac:DespatchSupplierParty/cac:Party/cac:PartyLegalEntity/cbc:RegistrationName | I35: No existe el Tag UBL o es vacío | J35: ERROR | K35: 1037 | L35: =VLOOKUP(K35,[1]CódigosRetorno!$A$2:$B$1996,2,FALSE) -> El XML no contiene el tag o no existe informacion de RegistrationName del emisor del documento | M35: XSL
I36: El formato del Tag UBL es diferente a alfanumérico de hasta 250 caracteres (se considera cualquier carácter incluido espacio, no se permite ningún otro 'whitespace character': salto de línea, tab, fin de línea, etc. Tampoco se permite solo espacios en blanco) | J36: OBSERV | K36: 4338 | L36: =VLOOKUP(K36,[1]CódigosRetorno!$A$2:$B$1996,2,FALSE) -> RegistrationName - El nombre o razon social del emisor no cumple con el estandar | M36: XSL
B37: =B35+1 -> 10 | C37: Entidad emisora de la autorización especial - remitente Número de autorización especial emitido por la entidad - remitente | D37: Global | E37: C | F37: an..50 | H37: /DespatchAdvice/cac:Shipment/cac:Delivery/cac:Despatch/cac:DespatchParty/cac:AgentParty/cac:PartyLegalEntity/cbc:CompanyID (Número de autorización) | I37: Si el Tag UBL existe, el formato del Tag UBL es diferente a alfanumérico de 3 a 50 caracteres (se considera cualquier carácter incluido espacio, no se permite ningún otro 'whitespace character': salto de línea, tab, fin de línea, etc. Tampoco se permite solo espacios en blanco) | J37: OBSERV | K37: 4369 | L37: =VLOOKUP(K37,[1]CódigosRetorno!$A$2:$B$1996,2,FALSE) -> El dato ingresado como numero de autorizacion del Remitente no cumple con el formato establecido | M37: XSL
I38: Si el Tag UBL existe y es diferente de vacío, existe otro cac:PartyLegalEntity | J38: ERROR | K38: 3353 | L38: =VLOOKUP(K38,[1]CódigosRetorno!$A$2:$B$1996,2,FALSE) -> Solo debe consignar un Numero de autorizacion | M38: XSL
F39: an2 | G39: (Catálogo N.° D-37) | H39: /DespatchAdvice/cac:Shipment/cac:Delivery/cac:Despatch/cac:DespatchParty/cac:AgentParty/cac:PartyLegalEntity/cbc:CompanyID@schemeID (Código de entidad autorizadora) | I39: Si existe el atributo y es diferente de vacío, el valor ingresado no se encuentra en el listado | J39: OBSERV | K39: 4395 | L39: =VLOOKUP(K39,[1]CódigosRetorno!$A$2:$B$1996,2,FALSE) -> El Codigo de entidad autorizadora es invalido | M39: XSL | N39: Catálogo (D-37)
I40: Si existe 'Número de autorización' con valor diferente de vacío, no existe el atributo o es vacío | J40: OBSERV | K40: 4394 | L40: =VLOOKUP(K40,[1]CódigosRetorno!$A$2:$B$1996,2,FALSE) -> Debe indicar la entidad autorizadora de la autorizacion especial | M40: XSL
...

Sheet TXT-JSON-GRE-Remitente
B2: GUIA REMISION REMITENTE
B3: Archivo texto: RRRRRRRRRRR-09-TXXX-99999999.TXT
B4: JSON: GRR
B5: Archivo Texto Orden | C5: Archivo JSON - Atributo | D5: DATO | E5: CONDICIÓN INFORMÁTICA | F5: TIPO Y LONGITUD | G5: FORMATO | H5: TAG UBL
B6: Archivo: Cabecera (RRRRRRRRRRR-09-TXXX-999999999.GRR)
B7: Datos de cabecera
B8: 1 | D8: Primera columna de la fila TXT | E8: M | F8: an3 | G8: GRR
B9: 2 | C9: nroCdpSwf | D9: Numeracion, conformada por serie y Número correlativo | E9: M | F9: an..13 | G9: T###-NNNNNNNN | H9: /DespatchAdvice/cbc:ID
B10: 3 | C10: fecEmision | D10: Fecha de emisión | E10: M | F10: an..10 | G10: YYYY-MM-DD | H10: /DespatchAdvice/cbc:IssueDate
B11: 4 | C11: horEmision | D11: Hora de Emisión | E11: M | F11: an8 | G11: HH:MM:SS | H11: /DespatchAdvice/cbc:IssueTime
B12: 5 | C12: tipCdpSwf | D12: Tipo de documento (Guia) | E12: M | F12: an2 | G12: "09" | H12: /DespatchAdvice/cbc:DespatchAdviceTypeCode
B13: 6 | C13: obsGuia | D13: Observaciones (Texto) | E13: C | F13: an..250 | H13: /DespatchAdvice/cbc:Note
B14: Datos del Remitente
B15: 7 | C15: tipDocuRemitenteSwf | D15: Tipo de documento de identidad del remitente | E15: M | F15: an1 | G15: "6" | H15: /DespatchAdvice/cac:DespatchSupplierParty/cac:Party/cac:PartyIdentification/cbc:ID@schemeID
B16: 8 | C16: nroRucRemitenteSwf | D16: Número de documento de identidad del remitente | E16: M | F16: an11 | G16: n11 | H16: /DespatchAdvice/cac:DespatchSupplierParty/cac:Party/cac:PartyIdentification/cbc:ID
B17: 9 | C17: razonSocialRemitenteSwf | D17: Apellidos y nombres, denominación o razón social del remitente | E17: M | F17: an..250 | H17: /DespatchAdvice/cac:DespatchSupplierParty/cac:Party/cac:PartyLegalEntity/cbc:RegistrationName
B18: 10 | C18: nroAutorizacionRemitenteSwf | D18: Entidad emisora de la autorización especial - remitente Número de autorización especial emitido por la entidad - remitente (Número de autorización) | E18: C | F18: an..50 | H18: /DespatchAdvice/cac:Shipment/cac:Delivery/cac:Despatch/cac:DespatchParty/cac:AgentParty/cac:PartyLegalEntity/cbc:CompanyID
B19: 11 | C19: codEntidadAutorizadoraRemitenteSwf | D19: Entidad emisora de la autorización especial - remitente Número de autorización especial emitido por la entidad - remitente (Código de entidad autorizadora) | E19: C | F19: an2 | G19: (Catálogo N.° D-37) | H19: /DespatchAdvice/cac:Shipment/cac:Delivery/cac:Despatch/cac:DespatchParty/cac:AgentParty/cac:PartyLegalEntity/cbc:CompanyID@schemeID
B20: Datos del Destinatario
B21: 12 | C21: tipDocDestinatario | D21: Tipo de documento de identidad del destinatario | E21: M | F21: an1 | G21: (Catálogo N° 06) | H21: /DespatchAdvice/cac:DeliveryCustomerParty/cac:Party/cac:PartyIdentification/cbc:ID@schemeID
B22: 13 | C22: numDocDestinatario | D22: Número de documento de identidad del destinatario | E22: M | F22: an..15 | H22: /DespatchAdvice/cac:DeliveryCustomerParty/cac:Party/cac:PartyIdentification/cbc:ID
B23: 14 | C23: rznSocialDestinatario | D23: Apellidos y nombres, denominación o razón social del destinatario | E23: M | F23: an..250 | H23: /DespatchAdvice/cac:DeliveryCustomerParty/cac:Party/cac:PartyLegalEntity/cbc:RegistrationName
B24: Datos del Proveedor
B25: 15 | C25: tipDocProveedor | D25: Tipo de documento de identidad del proveedor | E25: C | F25: an1 | G25: (Catálogo N° 06) | H25: /DespatchAdvice/cac:SellerSupplierParty/cac:Party/cac:PartyIdentification/cbc:ID@schemeID
B26: 16 | C26: numDocProveedor | D26: Número de documento de identidad del proveedor | E26: C | F26: an..15 | H26: /DespatchAdvice/cac:SellerSupplierParty/cac:Party/cac:PartyIdentification/cbc:ID
B27: 17 | C27: rznSociaProveedor | D27: Apellidos y nombres, denominación o razón social del proveedor | E27: C | F27: an..250 | H27: /DespatchAdvice/cac:SellerSupplierParty/cac:Party/cac:PartyLegalEntity/cbc:RegistrationName
B28: Datos del Comprador
B29: 18 | C29: tipDocComprador | D29: Tipo de documento de identidad del comprador | E29: C | F29: an1 | G29: (Catálogo N° 06) | H29: /DespatchAdvice/cac:BuyerCustomerParty/cac:Party/cac:PartyIdentification/cbc:ID@schemeID
B30: 19 | C30: numDocComprador | D30: Número de documento de identidad del comprador | E30: C | F30: an..15 | H30: /DespatchAdvice/cac:BuyerCustomerParty/cac:Party/cac:PartyIdentification/cbc:ID
B31: 20 | C31: rznSocialComprador | D31: Apellidos y nombres, denominación o razón social del comprador | E31: C | F31: an..250 | H31: /DespatchAdvice/cac:BuyerCustomerParty/cac:Party/cac:PartyLegalEntity/cbc:RegistrationName
B33: Archivo: Detalle (RRRRRRRRRRR-09-TXXX-999999999.ENV)
B34: Datos del envío
B35: 1 | D35: Primera columna de la fila TXT | E35: M | F35: an3 | G35: ENV
B36: 2 | C36: motTrasladoDatosEnvio | D36: Motivo del traslado | E36: M | F36: an2 | G36: (Catálogo N.° 20) | H36: /DespatchAdvice/cac:Shipment/cbc:HandlingCode
B37: 3 | C37: desMotivoTrasladoDatosEnvio | D37: Descripción de motivo de traslado | E37: C | F37: an..100 | H37: /DespatchAdvice/cac:Shipment/cbc:HandlingInstructions
B38: 4 | C38: psoBrutoTotalBienesDatosEnvio | D38: Peso bruto total de los ítems seleccionados (en KGM) | E38: C | F38: an..16 | G38: n(12,3) | H38: /DespatchAdvice/cac:Shipment/cbc:NetWeightMeasure
B39: 5 | C39: uniMedidaPesoBrutoBienesDatosEnvio | D39: Unidad de medida del peso bruto total de los items seleccionados | E39: C | F39: an3 | G39: (Catálogo N.° 03) "KGM" Kilogramos | H39: /DespatchAdvice/cac:Shipment/cbc:NetWeightMeasure@unitCode
B40: 6 | C40: sustentoDifPesoDatosEnvio | D40: Sustento de la diferencia del Peso bruto total de la carga respecto al peso de los ítems seleccionados | E40: C | F40: an..250 | H40: /DespatchAdvice/cac:Shipment/cbc:Information
B41: 7 | C41: psoBrutoTotalCargaDatosEnvio | D41: Peso bruto total de la carga | E41: M | F41: an..16 | G41: n(12,3) | H41: /DespatchAdvice/cac:Shipment/cbc:GrossWeightMeasure
B42: 8 | C42: uniMedidaPesoBrutoDatosEnvio | D42: Unidad de medida del peso bruto | E42: M | F42: an3 | G42: (Catálogo N.° 03) "KGM" Kilogramos "TNE" Toneladas | H42: /DespatchAdvice/cac:Shipment/cbc:GrossWeightMeasure@unitCode
...

Sheet GRE-R-TXT
A1: 1 | B1: 2 | C1: 3 | D1: 4 | E1: 5 | F1: 6 | G1: 7 | H1: 8 | I1: 9 | J1: 10 | K1: 11 | L1: 12 | M1: 13 | N1: 14 | O1: 15 | P1: 16 | Q1: 17 | R1: 18 | S1: 19 | T1: 20
B2: nroCdpSwf | C2: fecEmision | D2: horEmision | E2: tipCdpSwf | F2: obsGuia | G2: tipDocuEmisorSwf | H2: nroRucEmisorSwf | I2: razonSocialSwf | J2: nroAutorizacionSwf | K2: codEntidadAutorizadoraSwf | L2: tipDocDestinatario | M2: numDocDestinatario | N2: rznSocialDestinatario | O2: tipDocDestinatario | P2: numDocDestinatario | Q2: rznSocialDestinatario | R2: tipDocDestinatario | S2: numDocDestinatario | T2: rznSocialDestinatario
A3: GRR
A6: 1 | B6: 2 | C6: 3 | D6: 4 | E6: 5 | F6: 6 | G6: 7 | H6: 8 | I6: 9 | J6: 10 | K6: 11 | L6: 12 | M6: 13 | N6: 14 | O6: 15 | P6: 16 | Q6: 17 | R6: 18 | S6: 19 | T6: 20 | U6: 21 | V6: 22 | W6: 23
B7: motTrasladoDatosEnvio | C7: desMotivoTrasladoDatosEnvio | D7: psoBrutoTotalBienesDatosEnvio | E7: uniMedidaPesoBrutoDatosEnvio | F7: sustentoDifPesoDatosEnvio | G7: psoBrutoTotalCargaDatosEnvio | H7: uniMedidaPesoBrutoDatosEnvio | I7: numBultosDatosEnvio | J7: numContenedor1 | K7: numPrecinto1 | L7: numContenedor2 | M7: numPrecinto2 | N7: modTrasladoDatosEnvio | O7: fecInicioTrasladoDatosEnvio | P7: fecEntregaTransportistaDatosEnvio | Q7: indTransbordoProgramado | R7: indTrasladoVehCatM1oL | S7: indRetornoVehiculoEnvasesEmbalajes | T7: indRetornoVehiculoVacio | U7: indTrasladoTotalDAMoDS | V7: indRegistroVehiculoConductor | W7: tipEventoDatosEnvio
A8: ENV
A11: 1 | B11: 2 | C11: 3 | D11: 4 | E11: 5 | F11: 6 | G11: 7
B12: tipDocTransportista | C12: numDocTransportista | D12: nomTransportista | E12: numeroRegistroMTCTransportista | F12: numAutorizacionTransportista | G12: codEntidadAutorizadoraTransportista
A13: TTA
A16: 1 | B16: 2 | C16: 3 | D16: 4 | E16: 5 | F16: 6
B17: tipVehiculo | C17: numPlacaVehículoPrincipal | D17: tarjetaUnicaCirculacionElecPrincipal | E17: numAutorizacionPrincipal | F17: codEntidadEmisoraPrincipal
A18: VPS | B18: Principal
A19: VPS | B19: Secundario
A21: 1 | B21: 2 | C21: 3 | D21: 4 | E21: 5 | F21: 6 | G21: 7
B22: tipConductor | C22: tipDocumentoConductor | D22: numDocumentoConductor | E22: nombresConductor | F22: apellidosConductor | G22: numLicenciaConducir
A23: CON | B23: Principal
A24: CON | B24: Secundario
A26: 1 | B26: 2 | C26: 3 | D26: 4 | E26: 5 | F26: 6 | G26: 7 | H26: 8
B27: tipDireccionPunto | C27: ubiPartida | D27: dirPartida | E27: longitudPuntoGeorreferenciaPartida | F27: latitudPuntoGeorreferenciaPartida | G27: rucAsociadoPuntoPartida | H27: codEstablecimientoPuntoPartida
A28: PLL | B28: Partida
A29: PLL | B29: Llegada
A31: 1 | B31: 2 | C31: 3 | D31: 4
B32: codPuertoAeropuerto | C32: tipLocacionCodPuertoAeropuerto | D32: nombrePuertoAeropuerto
A33: EPA
A36: 1 | B36: 2 | C36: 3 | D36: 4 | E36: 5 | F36: 6 | G36: 7 | H36: 8 | I36: 9 | J36: 10 | K36: 11 | L36: 12
B37: lineaBien | C37: canBien | D37: uniMedidaBien | E37: desItem | F37: codItem | G37: codProductoSunatItem | H37: codProductoGTINItem | I37: tipEstructuraGTINItem | J37: nomConceptoItem | K37: codConceptoItem | L37: valueItem
A38: BIE
A41: 1 | B41: 2 | C41: 3 | D41: 4 | E41: 5 | F41: 6
B42: tipDocRel | C42: codTipDocRel | D42: numDocRel | E42: numDocEmisorDoc | F42: tipDocEmisorDocRel
A43: DOR

Sheet GRE-Transportista
B1: GUIA REMISION ELECTRÓNICA TRANSPORTISTA
B2: N° | C2: DATO | D2: NIVEL | E2: CONDICIÓN INFORMÁTICA | F2: TIPO Y LONGITUD | G2: FORMATO | H2: TAG UBL | I2: VALIDACIÓN / CONDICIÓN | J2: TIPO DE RETORNO | K2: CODIGO RETORNO | L2: MENSAJE DE RETORNO | M2: REST o XSL | N2: LISTADOS
B3: - | C3: -
B4: Datos de guía de remisión
B5: 1 | C5: Version del UBL | D5: Global | E5: M | F5: an..3 | G5: 2.1 | H5: /DespatchAdvice/cbc:UBLVersionID | I5: No existe el Tag UBL o es vacío | J5: ERROR | K5: 2111 | L5: =VLOOKUP(K5,[1]CódigosRetorno!$A$2:$B$1996,2,FALSE) -> El XML no contiene el tag o no existe informacion de UBLVersionID | M5: XSL
I6: El valor del Tag UBL es diferente a "2.1" | J6: ERROR | K6: 2110 | L6: =VLOOKUP(K6,[1]CódigosRetorno!$A$2:$B$1996,2,FALSE) -> UBLVersionID - La versión del UBL no es correcta | M6: XSL
B7: 2 | C7: Version de la estructura del documento | D7: Global | E7: M | F7: an..3 | G7: 2.0 | H7: /DespatchAdvice/cbc:CustomizationID | I7: No existe el Tag UBL o es vacío | J7: ERROR | K7: 2113 | L7: =VLOOKUP(K7,[1]CódigosRetorno!$A$2:$B$1996,2,FALSE) -> El XML no contiene el tag o no existe informacion de CustomizationID | M7: XSL
I8: El valor del Tag UBL es diferente a "2.0" | J8: ERROR | K8: 2112 | L8: =VLOOKUP(K8,[1]CódigosRetorno!$A$2:$B$1996,2,FALSE) -> CustomizationID - La version del documento no es correcta | M8: XSL
B9: 3 | C9: Numeracion, conformada por serie y Número correlativo | D9: Global | E9: M | F9: an..13 | G9: V###-NNNNNNNN | H9: /DespatchAdvice/cbc:ID | I9: El formato del Tag UBL es diferente a: [V][A-Z0-9]{3}-[0-9]{1,8} | J9: ERROR | K9: 1001 | L9: =VLOOKUP(K9,[1]CódigosRetorno!$A$2:$B$1996,2,FALSE) -> ID - El dato SERIE-CORRELATIVO no cumple con el formato de acuerdo al tipo de comprobante | M9: XSL
I10: El número de serie del Tag UBL es diferente al número de serie del archivo | J10: ERROR | K10: 1035 | L10: =VLOOKUP(K10,[1]CódigosRetorno!$A$2:$B$1996,2,FALSE) -> Numero de Serie del nombre del archivo no coincide con el consignado en el contenido del archivo XML | M10: XSL
I11: El número de documento del Tag UBL es diferente al número de documento del archivo | J11: ERROR | K11: 1036 | L11: =VLOOKUP(K11,[1]CódigosRetorno!$A$2:$B$1996,2,FALSE) -> Número de documento en el nombre del archivo no coincide con el consignado en el contenido del XML | M11: XSL
I12: El valor del Tag UBL se encuentra en el listado con indicador de estado igual a '1' | J12: ERROR | K12: 1033 | L12: =VLOOKUP(K12,[1]CódigosRetorno!$A$2:$B$1996,2,FALSE) -> El comprobante fue registrado previamente con otros datos | M12: REST | N12: Comprobantes de pagos electrónicos
I13: El valor del Tag UBL se encuentra en el listado con indicador de estado igual a '2' | J13: ERROR | K13: 1032 | L13: =VLOOKUP(K13,[1]CódigosRetorno!$A$2:$B$1996,2,FALSE) -> El comprobante ya esta informado y se encuentra con estado anulado o rechazado | M13: REST | N13: Comprobantes de pagos electrónicos
B14: =+B9+1 -> 4 | C14: Fecha de emisión | D14: Global | E14: M | F14: an10 | G14: YYYY-MM-DD | H14: /DespatchAdvice/cbc:IssueDate | I14: El valor del Tag UBL no cumple con el formato establecido | J14: ERROR | K14: 3436 | L14: =VLOOKUP(K14,[1]CódigosRetorno!$A$2:$B$1996,2,FALSE) -> El campo de fecha de emision no cumple con el formato establecido | M14: XSL
I15: La diferencia entre la fecha de recepción del XML y el valor del Tag UBL es mayor al límite del listado (1 día) | J15: ERROR | K15: 2108 | L15: =VLOOKUP(K15,[1]CódigosRetorno!$A$2:$B$1996,2,FALSE) -> Presentacion fuera de fecha | M15: REST | N15: Parámetros (004)
I16: El valor del Tag UBL es mayor a la fecha de recepción (TODAY) o es 12/07/2022 | J16: ERROR | K16: 2329 | L16: =VLOOKUP(K16,[1]CódigosRetorno!$A$2:$B$1996,2,FALSE) -> La fecha de emision se encuentra fuera del limite permitido | M16: XSL
B17: =+B14+1 -> 5 | C17: Hora de emisión | D17: Global | E17: M | F17: an8 | G17: hh:mm:ss | H17: /DespatchAdvice/cbc:IssueTime | I17: No existe el Tag UBL | J17: ERROR | K17: 3437 | L17: =VLOOKUP(K17,[1]CódigosRetorno!$A$2:$B$1996,2,FALSE) -> No existe informacion en el campo de hora de emision | M17: XSL
I18: El valor del Tag UBL no cumple con el formato establecido | J18: ERROR | K18: 3438 | L18: =VLOOKUP(K18,[1]CódigosRetorno!$A$2:$B$1996,2,FALSE) -> El campo de hora de emision no cumple con el formato establecido | M18: XSL
B19: =+B17+1 -> 6 | C19: Tipo de documento (Guia) | D19: Global | E19: M | F19: an..2 | G19: "31" | H19: /DespatchAdvice/cbc:DespatchAdviceTypeCode | I19: No existe el Tag UBL o es vacío | J19: ERROR | K19: 1050 | L19: =VLOOKUP(K19,[1]CódigosRetorno!$A$2:$B$1996,2,FALSE) -> El XML no contiene informacion en el tag DespatchAdviceTypeCode. | M19: XSL
I20: El valor del Tag UBL es diferente a "31" | J20: ERROR | K20: 1051 | L20: =VLOOKUP(K20,[1]CódigosRetorno!$A$2:$B$1996,2,FALSE) -> DespatchAdviceTypeCode - El valor del tipo de guía es inválido. | M20: XSL
G21: "PE:SUNAT" | H21: @listAgencyName | I21: Si existe el atributo, el valor ingresado es diferente a 'PE:SUNAT' | J21: OBSERV | K21: 4251 | L21: =VLOOKUP(K21,[1]CódigosRetorno!$A$2:$B$1996,2,FALSE) -> El dato ingresado como atributo @listAgencyName es incorrecto. | M21: XSL
G22: "Tipo de Documento" | H22: @listName | I22: Si existe el atributo, el valor ingresado es diferente a 'Tipo de Documento' | J22: OBSERV | K22: 4252 | L22: =VLOOKUP(K22,[1]CódigosRetorno!$A$2:$B$1996,2,FALSE) -> El dato ingresado como atributo @listName es incorrecto. | M22: XSL
G23: "urn:pe:gob:sunat:cpe:see:gem:catalogos:catalogo01" | H23: @listURI | I23: Si existe el atributo, el valor ingresado es diferente a 'urn:pe:gob:sunat:cpe:see:gem:catalogos:catalogo01' | J23: OBSERV | K23: 4253 | L23: =VLOOKUP(K23,[1]CódigosRetorno!$A$2:$B$1996,2,FALSE) -> El dato ingresado como atributo @listURI es incorrecto. | M23: XSL
B24: =+B19+1 -> 7 | C24: Observaciones (Texto) | D24: Global | E24: C | F24: an..250 | H24: /DespatchAdvice/cbc:Note | I24: Si el Tag UBL existe, el formato del Tag UBL es diferente a alfanumérico de hasta 250 caracteres o es vacío (se considera cualquier carácter incluido espacio, no se permite ningún otro "whitespace character": salto de línea, tab, fin de línea, etc. Tampoco se permite solo espacios en blanco) | J24: OBSERV | K24: 4186 | L24: =VLOOKUP(K24,[1]CódigosRetorno!$A$2:$B$1996,2,FALSE) -> cbc:Note - El campo observaciones supera la cantidad maxima especificada (250 carácteres). | M24: XSL
B25: Datos del Transportista
B26: =B24+1 -> 8 | C26: Tipo y número de documento de identidad del transportista | D26: Global | E26: M | F26: an1 | G26: "6" | H26: /DespatchAdvice/cac:DespatchSupplierParty/cac:Party/cac:PartyIdentification/cbc:ID@schemeID | I26: No existe el Tag UBL o es vacío | J26: ERROR | K26: 2678 | L26: =VLOOKUP(K26,[1]CódigosRetorno!$A$2:$B$1996,2,FALSE) -> El XML no contiene el atributo o no existe información del tipo de documento del emisor | M26: XSL
I27: El valor del Tag UBL es diferente a "6" | J27: ERROR | K27: 2511 | L27: =VLOOKUP(K27,[1]CódigosRetorno!$A$2:$B$1996,2,FALSE) -> El tipo de documento no es aceptado. | M27: XSL
G28: "Documento de Identidad" | H28: @schemeName | I28: Si existe el atributo, el valor ingresado es diferente a 'Documento de Identidad' | J28: OBSERV | K28: 4255 | L28: =VLOOKUP(K28,[1]CódigosRetorno!$A$2:$B$1996,2,FALSE) -> El dato ingresado como atributo @schemeName es incorrecto. | M28: XSL
G29: "PE:SUNAT" | H29: @schemeAgencyName | I29: Si existe el atributo, el valor ingresado es diferente a 'PE:SUNAT' | J29: OBSERV | K29: 4256 | L29: =VLOOKUP(K29,[1]CódigosRetorno!$A$2:$B$1996,2,FALSE) -> El dato ingresado como atributo @schemeAgencyName es incorrecto. | M29: XSL
G30: "urn:pe:gob:sunat:cpe:see:gem:catalogos:catalogo06" | H30: @schemeURI | I30: Si existe el atributo, el valor ingresado es diferente a 'urn:pe:gob:sunat:cpe:see:gem:catalogos:catalogo06' | J30: OBSERV | K30: 4257 | L30: =VLOOKUP(K30,[1]CódigosRetorno!$A$2:$B$1996,2,FALSE) -> El dato ingresado como atributo @schemeURI es incorrecto. | M30: XSL
F31: an11 | G31: n11 | H31: /DespatchAdvice/cac:DespatchSupplierParty/cac:Party/cac:PartyIdentification/cbc:ID | I31: El Tag UBL es diferente al RUC del nombre del XML | J31: ERROR | K31: 1034 | L31: =VLOOKUP(K31,[1]CódigosRetorno!$A$2:$B$1996,2,FALSE) -> Número de RUC del nombre del archivo no coincide con el consignado en el contenido del archivo XML | M31: XSL
I32: El valor del Tag UBL tiene un ind_estado diferente "00" en el listado | J32: ERROR | K32: 3349 | L32: =VLOOKUP(K32,[1]CódigosRetorno!$A$2:$B$1996,2,FALSE) -> El RUC del Transportista no esta activo | M32: REST | N32: Contribuyentes
I33: El valor del Tag UBL tiene un ind_condicion diferente a "00" en el listado | J33: ERROR | K33: 3350 | L33: =VLOOKUP(K33,[1]CódigosRetorno!$A$2:$B$1996,2,FALSE) -> El RUC del Transportista no esta habido | M33: REST | N33: Contribuyentes
I34: Se encuentra afecto exclusivamente solo a los tributos Renta de primera categoría, Renta de segunda categoría o Renta de cuarta categoría (no está afecto a ningún otro tributo distinto de los indicados) | J34: ERROR | K34: 3439 | L34: =VLOOKUP(K34,[1]CódigosRetorno!$A$2:$B$1996,2,FALSE) -> El RUC no esta afecto a los tributos autorizados | M34: REST | N34: Afectacion
B35: =B26+1 -> 9 | C35: Apellidos y Nombres o denominacion o razón social del transportista | D35: Global | E35: M | F35: an..250 | H35: /DespatchAdvice/cac:DespatchSupplierParty/cac:Party/cac:PartyLegalEntity/cbc:RegistrationName | I35: No existe el Tag UBL o es vacío | J35: ERROR | K35: 1037 | L35: =VLOOKUP(K35,[1]CódigosRetorno!$A$2:$B$1996,2,FALSE) -> El XML no contiene el tag o no existe informacion de RegistrationName del emisor del documento | M35: XSL
I36: El formato del Tag UBL es diferente a alfanumérico de hasta 250 caracteres (se considera cualquier carácter incluido espacio, no se permite ningún otro "whitespace character": salto de línea, tab, fin de línea, etc. Tampoco se permite solo espacios en blanco) | J36: OBSERV | K36: 4338 | L36: =VLOOKUP(K36,[1]CódigosRetorno!$A$2:$B$1996,2,FALSE) -> RegistrationName - El nombre o razon social del emisor no cumple con el estandar | M36: XSL
B37: =B35+1 -> 10 | C37: Número de Registro MTC | D37: Global | E37: C | F37: an..20 | H37: /DespatchAdvice/cac:Shipment/cac:ShipmentStage/cac:CarrierParty/cac:PartyLegalEntity/cbc:CompanyID | I37: No existe el Tag UBL o es vacío | J37: OBSERV | K37: 4391 | L37: =VLOOKUP(K37,[1]CódigosRetorno!$A$2:$B$1996,2,FALSE) -> El Numero de Registro MTC del transportista no existe o no contiene informacion | M37: XSL
I38: Si el Tag UBL existe y es diferente de vacío, el formato del Tag UBL es diferente a alfanumérico de hasta 20 caracteres (solo se permite letras y números, no se permite ningún otro 'whitespace character': espacio, salto de línea, tab, fin de línea, etc. Tampoco se permite solo espacios en blanco o solamente ceros) | J38: OBSERV | K38: 4392 | L38: =VLOOKUP(K38,[1]CódigosRetorno!$A$2:$B$1996,2,FALSE) -> El Numero de Registro MTC del transportista no cumple con el formato establecido | M38: XSL
I39: Si el Tag UBL existe y es diferente de vacío, el valor del Tag UBL no se encuentra en el listado | J39: OBSERV | K39: 4393 | L39: =VLOOKUP(K39,[1]CódigosRetorno!$A$2:$B$1996,2,FALSE) -> El Numero de Registro MTC del transportista no se encuentra en las bases consultadas | M39: REST | N39: Información de Registro MTC
I40: Si el Tag UBL existe y es diferente de vacío, existe otro cac:PartyLegalEntity | J40: ERROR | K40: 3353 | L40: =VLOOKUP(K40,[1]CódigosRetorno!$A$2:$B$1996,2,FALSE) -> Solo debe consignar un Numero de autorizacion | M40: XSL
...

Sheet TXT-JSON-GRE-Transportista
B2: GUIA REMISION TRANSPORTISTA
B3: Archivo texto: RRRRRRRRRRR-31-VXXX-99999999.TXT
B4: JSON: GRT
B5: Archivo Texto Orden | C5: Archivo JSON - Atributo | D5: DATO | E5: CONDICIÓN INFORMÁTICA | F5: TIPO Y LONGITUD | G5: FORMATO | H5: TAG UBL
B6: Archivo: Cabecera (RRRRRRRRRRR-31-VXXX-999999999.GRT)
B7: Datos de cabecera
B8: 1 | D8: Primera columna de la fila TXT | E8: M | F8: an3 | G8: GRT
B9: 2 | C9: nroCdpSwf | D9: Numeracion, conformada por serie y Número correlativo | E9: M | F9: an..13 | G9: T###-NNNNNNNN | H9: /DespatchAdvice/cbc:ID
B10: 3 | C10: fecEmision | D10: Fecha de emisión | E10: M | F10: an..10 | G10: YYYY-MM-DD | H10: /DespatchAdvice/cbc:IssueDate
B11: 4 | C11: horEmision | D11: Hora de Emisión | E11: M | F11: an8 | G11: HH:MM:SS | H11: /DespatchAdvice/cbc:IssueTime
B12: 5 | C12: tipCdpSwf | D12: Tipo de documento (Guia) | E12: M | F12: an2 | G12: "31" | H12: /DespatchAdvice/cbc:DespatchAdviceTypeCode
B13: 6 | C13: obsGuia | D13: Observaciones (Texto) | E13: C | F13: an..250 | H13: /DespatchAdvice/cbc:Note
B14: Datos del Remitente
B15: 7 | C15: tipDocuRemitenteSwf | D15: Tipo de documento de identidad del remitente | E15: M | F15: an1 | G15: "6" | H15: /DespatchAdvice/cac:DespatchSupplierParty/cac:Party/cac:PartyIdentification/cbc:ID@schemeID
B16: 8 | C16: nroRuc RemitenteSwf | D16: Número de documento de identidad del remitente | E16: M | F16: an11 | G16: n11 | H16: /DespatchAdvice/cac:DespatchSupplierParty/cac:Party/cac:PartyIdentification/cbc:ID
B17: 9 | C17: razonSocialRemitenteSwf | D17: Apellidos y nombres, denominación o razón social del remitente | E17: M | F17: an..250 | H17: /DespatchAdvice/cac:DespatchSupplierParty/cac:Party/cac:PartyLegalEntity/cbc:RegistrationName
B18: Datos del Destinatario
B19: 10 | C19: tipDocDestinatario | D19: Tipo de documento de identidad del destinatario | E19: M | F19: an1 | G19: (Catálogo N° 06) | H19: /DespatchAdvice/cac:DeliveryCustomerParty/cac:Party/cac:PartyIdentification/cbc:ID@schemeID
B20: 11 | C20: numDocDestinatario | D20: Número de documento de identidad del destinatario | E20: M | F20: an..15 | H20: /DespatchAdvice/cac:DeliveryCustomerParty/cac:Party/cac:PartyIdentification/cbc:ID
B21: 12 | C21: rznSocialDestinatario | D21: Apellidos y nombres, denominación o razón social del destinatario | E21: M | F21: an..250 | H21: /DespatchAdvice/cac:DeliveryCustomerParty/cac:Party/cac:PartyLegalEntity/cbc:RegistrationName
B22: Datos de empresa que subcontrata
B23: 13 | C23: tipDocSubcontratador | D23: Tipo de documento de identidad del subcontratador | E23: C | F23: an1 | G23: "6" | H23: /DespatchAdvice/cac:Shipment/cac:Consignment/cac:LogisticsOperatorParty/cac:PartyIdentification/cbc:ID@schemeID
B24: 14 | C24: numDocSubcontratador | D24: Número de documento de identidad del subcontratador (Número de RUC) | E24: C | F24: an11 | H24: /DespatchAdvice/cac:Shipment/cac:Consignment/cac:LogisticsOperatorParty/cac:PartyIdentification/cbc:ID
B25: 15 | C25: rznSocialSubcontratador | D25: Apellidos y nombres, denominacion o razón social del subcontratador | E25: C | F25: an..250 | H25: /DespatchAdvice/cac:Shipment/cac:Consignment/cac:LogisticsOperatorParty/cac:PartyLegalEntity/cbc:RegistrationName
B26: Datos quien paga el servicio de transporte - solo se completa cuando paga un tercero
B27: 16 | C27: tipDocPagaServicio | D27: Tipo de documento de identidad de quien paga el servicio | E27: C | F27: an1 | G27: (Catálogo N° 06) | H27: /DespatchAdvice/cac:OriginatorCustomerParty/cac:Party/cac:PartyIdentification/cbc:ID@schemeID
B28: 17 | C28: numDocPagaServicio | D28: Número de documento de identidad de quien paga el servicio | E28: C | F28: an..15 | H28: /DespatchAdvice/cac:OriginatorCustomerParty/cac:Party/cac:PartyIdentification/cbc:ID
B29: 18 | C29: rznSocialPagaServicio | D29: Apellidos y nombres, denominacion o razón social de quien paga el servicio | E29: C | F29: an..250 | H29: /DespatchAdvice/cac:OriginatorCustomerParty/cac:Party/cac:PartyLegalEntity/cbc:RegistrationName
B31: Archivo: Detalle (RRRRRRRRRRR-31-VXXX-999999999.TSL)
B32: Datos del traslado
B33: 1 | D33: Primera columna de la fila TXT | E33: M | F33: an3 | G33: TSL
B34: 2 | C34: fecInicioTraslado | D34: Fecha Inicio de traslado | E34: M | F34: an..10 | G34: YYYY-MM-DD | H34: /DespatchAdvice/cac:Shipment/cac:ShipmentStage/cac:TransitPeriod/cbc:StartDate
B35: 3 | C35: anotacionOpcionalBienesTraslado | D35: Anotación opcional sobre los bienes a transportar | E35: C | F35: an..500 | H35: /DespatchAdvice/cac:DespatchLine/cac:Item/cbc:Description
B36: 4 | C36: psoBrutoTotalCargaTraslado | D36: Peso bruto total de la carga | E36: M | F36: an..16 | G36: n(12,3) | H36: /DespatchAdvice/cac:Shipment/cbc:GrossWeightMeasure
B37: 5 | C37: uniMedidaPesoBrutoTraslado | D37: Unidad de medida del peso bruto | E37: M | F37: an3 | G37: "KGM" Kilogramos "TNE" Toneladass | H37: /DespatchAdvice/cac:Shipment/cbc:GrossWeightMeasure@unitCode
B38: 6 | C38: indTrasladoTotalBienes | D38: Indicador de traslado total de bienes | E38: C | F38: an…50 | G38: "SUNAT_Envio_IndicadorTrasladoTotal" | H38: /DespatchAdvice/cac:Shipment/cbc:SpecialInstructions
B39: 7 | C39: indRetornoVehiculoEnvasesEmbalajes | D39: Indicador de retorno de vehículo con envases o embalajes vacíos | E39: C | F39: an…50 | G39: "SUNAT_Envio_IndicadorRetornoVehiculoEnvaseVacio" | H39: /DespatchAdvice/cac:Shipment/cbc:SpecialInstructions
B40: 8 | C40: indRetornoVehiculoVacio | D40: Indicador de retorno de vehículo vacío | E40: C | F40: an…50 | G40: "SUNAT_Envio_IndicadorRetornoVehiculoVacio" | H40: /DespatchAdvice/cac:Shipment/cbc:SpecialInstructions
B41: 9 | C41: indTransbordoProgramado | D41: Indicador de Transbordo Programado | E41: C | F41: an…50 | G41: "SUNAT_Envio_IndicadorTransbordoProgramado" | H41: /DespatchAdvice/cac:Shipment/cbc:SpecialInstructions
B42: 10 | C42: indTransporteSubcontratado | D42: Indicador de transporte subcontratado | E42: C | F42: an…50 | G42: "SUNAT_Envio_IndicadorTrasporteSubcontratado" | H42: /DespatchAdvice/cac:Shipment/cbc:SpecialInstructions
...

Sheet GRE-T-TXT
A1: 1 | B1: 2 | C1: 3 | D1: 4 | E1: 5 | F1: 6 | G1: 7 | H1: 8 | I1: 9 | J1: 10 | K1: 11 | L1: 12 | M1: 13 | N1: 14 | O1: 15 | P1: 16 | Q1: 17 | R1: 18
B2: nroCdpSwf | C2: fecEmision | D2: horEmision | E2: tipCdpSwf | F2: obsGuia | G2: tipDocuEmisorSwf | H2: nroRucEmisorSwf | I2: razonSocialSwf | J2: tipDocDestinatario | K2: numDocDestinatario | L2: rznSocialDestinatario | M2: tipDocSubcontratador | N2: numDocSubcontratador | O2: rznSocialSubcontratador | P2: tipDocPagaServicio | Q2: numDocPagaServicio | R2: rznSocialPagaServicio
A3: GRT
A6: 1 | B6: 2 | C6: 3 | D6: 4 | E6: 5 | F6: 6 | G6: 7 | H6: 8 | I6: 9 | J6: 10 | K6: 11 | L6: 12
B7: fecInicioTraslado | C7: anotacionOpcionalBienesTraslado | D7: psoBrutoTotalCargaTraslado | E7: uniMedidaPesoBrutoTraslado | F7: indTrasladoTotalBienes | G7: indRetornoVehiculoEnvasesEmbalajes | H7: indRetornoVehiculoVacio | I7: indTransbordoProgramado | J7: indTransporteSubcontratado | K7: indPagadorFlete | L7: tipEventoTraslado
A8: TSL
A11: 1 | B11: 2 | C11: 3 | D11: 4 | E11: 5 | F11: 6 | G11: 7
B12: tipDocTransportista | C12: numDocTransportista | D12: nomTransportista | E12: numeroRegistroMTCTransportista | F12: numAutorizacionTransportista | G12: codEntidadAutorizadoraTransportista
A13: TTA
A16: 1 | B16: 2 | C16: 3 | D16: 4 | E16: 5 | F16: 6
B17: tipVehiculo | C17: numPlacaVehículoPrincipal | D17: tarjetaUnicaCirculacionElecPrincipal | E17: numAutorizacionPrincipal | F17: codEntidadEmisoraPrincipal
A18: VPS | B18: Principal
A19: VPS | B19: Secundario
A21: 1 | B21: 2 | C21: 3 | D21: 4 | E21: 5 | F21: 6 | G21: 7
B22: tipConductor | C22: tipDocumentoConductor | D22: numDocumentoConductor | E22: nombresConductor | F22: apellidosConductor | G22: numLicenciaConducir
A23: CON | B23: Principal
A24: CON | B24: Secundario
A26: 1 | B26: 2 | C26: 3 | D26: 4 | E26: 5 | F26: 6
B27: tipDireccionPunto | C27: ubiPartida | D27: dirPartida | E27: longitudPuntoGeorreferenciaPartida | F27: latitudPuntoGeorreferenciaPartida
A28: PLL | B28: Partida
A29: PLL | B29: Llegada
A31: 1 | B31: 2 | C31: 3 | D31: 4 | E31: 5 | F31: 6 | G31: 7 | H31: 8 | I31: 9 | J31: 10 | K31: 11 | L31: 12
B32: lineaBien | C32: canBien | D32: uniMedidaBien | E32: desItem | F32: codItem | G32: codProductoSunatItem | H32: codProductoGTINItem | I32: tipEstructuraGTINItem | J32: nomConceptoItem | K32: codConceptoItem | L32: valueItem
A33: BIE
A36: 1 | B36: 2 | C36: 3 | D36: 4 | E36: 5 | F36: 6
B37: tipDocRel | C37: codTipDocRel | D37: numDocRel | E37: numDocEmisorDoc | F37: tipDocEmisorDocRel
A38: DOR

Sheet Catalogos
A1: Anexo V
A2: Anexo N.°8 : Catálogo de códigos
A4: No. | B4: 01
A5: Catálogo | B5: Código de tipo de documento
A6: Código | B6: Descripción
A7: 01 | B7: Factura
A8: 03 | B8: Boleta de venta
A9: 04 | B9: Liquidación de compra
A10: 05 | B10: Boletos de Transporte Aéreo que emiten las Compañías de Aviación Comercial por el servicio de transporte aéreo regular de pasajeros, emitido de manera manual, mecanizada o por medios electrónicos (BME)
A11: 06 | B11: Carta de porte aéreo
A12: 07 | B12: Nota de crédito
A13: 08 | B13: Nota de débito
A14: 09 | B14: Guía de remisión remitente
A15: 11 | B15: Póliza emitida por las Bolsas de Valores
A16: 12 | B16: Ticket de máquina registradora
A17: 13 | B17: Documento emitido por bancos, instituciones financieras, crediticias y de seguros que se encuentren bajo el control de la Superintendencia de Banca y Seguros
A18: 14 | B18: Recibo servicios públicos
A19: 15 | B19: Boletos emitidos por el servicio de transporte terrestre regular urbano de pasajeros y el ferroviario público de pasajeros prestado en vía férrea local
A20: 16 | B20: Boleto de viaje emitido por las empresas de transporte público interprovincial de pasajeros
A21: 18 | B21: Documentos emitidos por las AFP
A22: 19 | B22: Boleto por atracciones y espectáculos públicos
A23: 20 | B23: Comprobante de retención
A24: 21 | B24: Conocimiento de embarque por el servicio de transporte de carga marítima
A25: 23 | B25: Pólizas de Adjudicación por remate o adjudicación de bienes
A26: 24 | B26: Certificado de pago de regalías emitidas por PERUPETRO S.A.
A27: 28 | B27: Etiquetas por el pago de la Tarifa Unificada de Uso de Aeropuerto – TUUA
A28: 29 | B28: Documentos emitidos por la COFOPRI
A29: 30 | B29: Documentos emitidos por las empresas que desempeñan el rol adquirente en los sistemas de pago mediante tarjetas de crédito y débito, emitidas por bancos e instituciones financieras o crediticias, domiciliados o no en el país.
A30: 31 | B30: Guía de remisión transportista
A31: 32 | B31: Documentos emitidos por recaudadoras de la Garantía de Red Principal
A32: 34 | B32: Documento del Operador
A33: 35 | B33: Documento del Partícipe
A34: 36 | B34: Recibo de Distribución de Gas Natural
A35: 37 | B35: Documentos que emitan los concesionarios del servicio de revisiones técnicas
A36: 40 | B36: Comprobante de Percepción
A37: 41 | B37: Comprobante de Percepción – Venta interna ( físico - formato impreso)
A38: 42 | B38: Documentos emitidos por los adq. en los sistemas de pago por tarj. de crédito emitidas por ellas mismas
A39: 43 | B39: Boleto de compañías de aviación transporte aéreo no regular
A40: 45 | B40: Documentos emitidos por centros educativos y culturales, universidades, asociaciones y fundaciones
A41: 55 | B41: BVME para transporte ferroviario de pasajeros
...

Sheet Codigos retorno
A1: Código | B1: Descripción de Error u Observación
A2: - | B2: -
A3: 0100 | B3: El sistema no puede responder su solicitud. Intente nuevamente o comuníquese con su Administrador
A4: 0101 | B4: El encabezado de seguridad es incorrecto
A5: 0102 | B5: Usuario o contrasena incorrectos
A6: 0103 | B6: El Usuario ingresado no existe
A7: 0104 | B7: La Clave ingresada es incorrecta
A8: 0105 | B8: El Usuario no está activo
A9: 0106 | B9: El Usuario no es válido
A10: 0109 | B10: El sistema no puede responder su solicitud. (El servicio de autenticación no está disponible)
A11: 0110 | B11: No se pudo obtener la informacion del tipo de usuario
A12: 0111 | B12: No tiene el perfil para enviar comprobantes electronicos
... A663: 2536 | B663: La serie y numero de la GRE consignada como documento relacionado no se encuentra registrado con baja por cambio de destinatario
A664: 2537 | B664: cac:OrderReference/cac:DocumentReference/cbc:DocumentTypeCode - El tipo de documento de serie y número dado de baja es incorrecta.
A665: 2538 | B665: El contribuyente no se encuentra autorizado como emisor electronico de Guía o de factura o de boletaFactura GEM.
A666: 2539 | B666: El contribuyente no esta activo.
A667: 2540 | B667: El contribuyente no esta habido.
A668: 2541 | B668: El XML no contiene el tag o no existe informacion del tipo de documento identidad del remitente.
A669: 2542 | B669: cac:DespatchSupplierParty/cbc:CustomerAssignedAccountID@schemeID - El valor ingresado como tipo de documento identidad del remitente es incorrecta.
A670: 2543 | B670: El XML no contiene el tag o no existe informacion de la dirección completa y detallada en domicilio fiscal.
A671: 2544 | B671: El XML no contiene el tag o no existe información de la provincia en domicilio fiscal.
A672: 2545 | B672: El XML no contiene el tag o no existe información del departamento en domicilio fiscal.
A673: 2546 | B673: El XML no contiene el tag o no existe información del distrito en domicilio fiscal.
A674: 2547 | B674: El XML no contiene el tag o no existe información del país en domicilio fiscal.
A675: 2548 | B675: El valor del país inválido.
A676: 2549 | B676: El XML no contiene el tag o no existe informacion del tipo de documento identidad del destinatario.
... A1980: 4437 | B1980: El control de los saldos pendientes de traslado es responsabilidad del contribuyente
